Workbook
Name Slicer_Invoice_Date: #N/A

Sheet Project Guide
B1: Analysis
A2: Sales Report | B2: Daily sales, monthly sales
A3: Product Report | B3: Product-wise sales, profit, top-selling products
A4: Customer Report | B4: Customer contribution, city-wise sales
A5: Expense Report | B5: Department-wise expenses, paid vs pending
A6: Dashboard | B6: KPIs, charts, slicers, business insights

Sheet Sales Data
A1: Invoice No | B1: Invoice Date | C1: SKU | D1: Product Name | E1: Category | F1: Customer ID | G1: Customer Name | H1: City | I1: Quantity | J1: UOM | K1: Unit Selling Price (INR) | L1: Discount % | M1: Gross Sales (INR) | N1: Net Sales (INR) | O1: COGS (INR) | P1: Gross Profit (INR) | Q1: Payment Mode | R1: Order Status | S1: Sales Region
A2: INV-26-09-0001 | B2: 46276 | C2: FB003 | D2: Tomato Ketchup 500g | E2: Sauces | F2: C013 | G2: Shree Balaji Store | H2: Meerut | I2: 145 | J2: Bottle | K2: 85 | L2: 0 | M2: 12325 | N2: 12325 | O2: 7395 | P2: 4930 | Q2: Credit | R2: Returned | S2: Central
A3: INV-26-09-0002 | B3: 46291 | C3: FB010 | D3: Mixed Namkeen 200g | E3: Snacks | F3: C004 | G3: Kumar Traders | H3: Rohtak | I3: 160 | J3: Pack | K3: 50 | L3: 0.03 | M3: 8000 | N3: 7760 | O3: 4640 | P3: 3120 | Q3: Credit | R3: Delivered | S3: Central
A4: INV-26-09-0003 | B4: 46274 | C4: FB001 | D4: Classic Potato Chips | E4: Snacks | F4: C005 | G4: Daily Needs Store | H4: Gurugram | I4: 17 | J4: Pack | K4: 20 | L4: 0.02 | M4: 340 | N4: 333.2 | O4: 195.5 | P4: 137.7 | Q4: Cash | R4: Returned | S4: Central
A5: INV-26-09-0004 | B5: 46287 | C5: FB004 | D5: Mango Drink 200ml | E5: Beverages | F5: C008 | G5: Jai Maa Enterprises | H5: Bahadurgarh | I5: 164 | J5: Tetra Pack | K5: 25 | L5: 0 | M5: 4100 | N5: 4100 | O5: 2296 | P5: 1804 | Q5: UPI | R5: Delivered | S5: Central
A6: INV-26-09-0005 | B6: 46274 | C6: FB010 | D6: Mixed Namkeen 200g | E6: Snacks | F6: C007 | G6: Metro Foods Retail | H6: Noida | I6: 98 | J6: Pack | K6: 50 | L6: 0 | M6: 4900 | N6: 4900 | O6: 2842 | P6: 2058 | Q6: Cash | R6: Delivered | S6: Central
A7: INV-26-09-0006 | B7: 46292 | C7: FB007 | D7: Chocolate Cookies 150g | E7: Bakery | F7: C013 | G7: Shree Balaji Store | H7: Meerut | I7: 142 | J7: Pack | K7: 40 | L7: 0.03 | M7: 5680 | N7: 5509.6 | O7: 3266 | P7: 2243.6 | Q7: UPI | R7: Delivered | S7: North
A8: INV-26-09-0007 | B8: 46291 | C8: FB005 | D8: Orange Drink 200ml | E8: Beverages | F8: C008 | G8: Jai Maa Enterprises | H8: Bahadurgarh | I8: 54 | J8: Tetra Pack | K8: 25 | L8: 0.02 | M8: 1350 | N8: 1323 | O8: 766.8 | P8: 556.2 | Q8: Cash | R8: Pending | S8: West
A9: INV-26-09-0008 | B9: 46277 | C9: FB003 | D9: Tomato Ketchup 500g | E9: Sauces | F9: C014 | G9: National Distributors | H9: Chandigarh | I9: 126 | J9: Bottle | K9: 85 | L9: 0.03 | M9: 10710 | N9: 10388.7 | O9: 6426 | P9: 3962.7 | Q9: Bank Transfer | R9: Pending | S9: Central
A10: INV-26-09-0009 | B10: 46283 | C10: FB001 | D10: Classic Potato Chips | E10: Snacks | F10: C014 | G10: National Distributors | H10: Chandigarh | I10: 24 | J10: Pack | K10: 20 | L10: 0.05 | M10: 480 | N10: 456 | O10: 276 | P10: 180 | Q10: UPI | R10: Returned | S10: North
A11: INV-26-09-0010 | B11: 46267 | C11: FB002 | D11: Masala Potato Chips | E11: Snacks | F11: C012 | G11: New India Mart | H11: Ghaziabad | I11: 105 | J11: Pack | K11: 20 | L11: 0.02 | M11: 2100 | N11: 2058 | O11: 1239 | P11: 819 | Q11: Cash | R11: Pending | S11: Central
A12: INV-26-09-0011 | B12: 46275 | C12: FB009 | D12: Roasted Peanuts 100g | E12: Snacks | F12: C002 | G12: Fresh Mart | H12: Sonipat | I12: 89 | J12: Pack | K12: 35 | L12: 0 | M12: 3115 | N12: 3115 | O12: 1780 | P12: 1335 | Q12: Credit | R12: Delivered | S12: West
A13: INV-26-09-0012 | B13: 46273 | C13: FB008 | D13: Cream Biscuits 100g | E13: Bakery | F13: C007 | G13: Metro Foods Retail | H13: Noida | I13: 191 | J13: Pack | K13: 20 | L13: 0.02 | M13: 3820 | N13: 3743.6 | O13: 2101 | P13: 1642.6 | Q13: Credit | R13: Returned | S13: North
... A451: INV-26-09-0450 | B451: 46278 | C451: FB010 | D451: Mixed Namkeen 200g | E451: Snacks | F451: C004 | G451: Kumar Traders | H451: Rohtak | I451: 176 | J451: Pack | K451: 50 | L451: 0 | M451: 8800 | N451: 8800 | O451: 5104 | P451: 3696 | Q451: Cash | R451: Delivered | S451: North

Sheet Expense Data
A1: Expense ID | B1: Expense Date | C1: Expense Type | D1: Department | E1: Amount (INR) | F1: Payment Status | G1: Vendor
A2: EXP-26-09-001 | B2: 46289 | C2: Marketing | D2: Warehouse | E2: 10706 | F2: Paid | G2: Supplier-09
A3: EXP-26-09-002 | B3: 46271 | C3: Warehouse Rent | D3: Production | E3: 13916 | F3: Pending | G3: Supplier-11
A4: EXP-26-09-003 | B4: 46285 | C4: Staff Wages | D4: Production | E4: 11102 | F4: Pending | G4: Supplier-12
A5: EXP-26-09-004 | B5: 46288 | C5: Warehouse Rent | D5: Production | E5: 17115 | F5: Pending | G5: Supplier-12
A6: EXP-26-09-005 | B6: 46288 | C6: Marketing | D6: Warehouse | E6: 11964 | F6: Paid | G6: Supplier-09
A7: EXP-26-09-006 | B7: 46272 | C7: Packaging | D7: Production | E7: 15262 | F7: Pending | G7: Supplier-03
A8: EXP-26-09-007 | B8: 46284 | C8: Marketing | D8: Admin | E8: 3045 | F8: Pending | G8: Supplier-11
A9: EXP-26-09-008 | B9: 46290 | C9: Maintenance | D9: Production | E9: 10522 | F9: Paid | G9: Supplier-07
A10: EXP-26-09-009 | B10: 46285 | C10: Maintenance | D10: Sales | E10: 14015 | F10: Paid | G10: Supplier-05
A11: EXP-26-09-010 | B11: 46286 | C11: Staff Wages | D11: Sales | E11: 11564 | F11: Paid | G11: Supplier-06
A12: EXP-26-09-011 | B12: 46295 | C12: Maintenance | D12: Admin | E12: 3171 | F12: Paid | G12: Supplier-01
A13: EXP-26-09-012 | B13: 46272 | C13: Marketing | D13: Production | E13: 18263 | F13: Pending | G13: Supplier-07
... A61: EXP-26-09-060 | B61: 46270 | C61: Factory Electricity | D61: Warehouse | E61: 3124 | F61: Paid | G61: Supplier-09

Sheet Pivot
A3: Product Name | B3: Sum of Net Sales (INR)
A4: Chocolate Cookies 150g | B4: 8080
A5: Classic Potato Chips | B5: 4602.6
A6: Cream Biscuits 100g | B6: 5616.8
A7: Instant Noodles 70g | B7: 1388.1
A8: Mango Drink 200ml | B8: 2026
A9: Orange Drink 200ml | B9: 5050
A10: Grand Total | B10: 26763.5
A21: City | B21: Sum of Net Sales (INR)
A22: Bahadurgarh | B22: 2760
A23: Chandigarh | B23: 7401.6
A24: Faridabad | B24: 1493.8
A25: Ghaziabad | B25: 5050
A26: Noida | B26: 2100
A27: Rohtak | B27: 6708.1
A28: Sonipat | B28: 1250
A29: Grand Total | B29: 26763.5
A42: Category | B42: Sum of Net Sales (INR)
A43: Bakery | B43: 13696.8
A44: Beverages | B44: 7076
A45: Ready-to-Eat | B45: 1388.1
A46: Snacks | B46: 4602.6
A47: Grand Total | B47: 26763.5
N52: `
A57: Customer Name | B57: Sum of Net Sales (INR)
A58: Fresh Mart | B58: 1250
A59: Green Basket | B59: 1493.8
A60: Jai Maa Enterprises | B60: 2760
A61: Kumar Traders | B61: 6708.1
A62: Metro Foods Retail | B62: 2100
A63: National Distributors | B63: 7401.6
A64: New India Mart | B64: 5050
A65: Grand Total | B65: 26763.5
A81: Payment Mode | B81: Sum of Net Sales (INR)
A82: Bank Transfer | B82: 3477.45
A83: Cash | B83: 7489.25
A84: Credit | B84: 5616.8
A85: UPI | B85: 10180
A86: Grand Total | B86: 26763.5
A95: Sales Region | B95: Sum of Net Sales (INR)
...

Sheet Dashboard
B2: Sales Dashboard | M2: TOTAL QTY | P2: DISCOUNT % | S2: NET SALE | V2: COGS | Y2: PROFIT
M3: =GETPIVOTDATA("Sum of Quantity",Pivot!$A$110) -> 1110 | P3: =GETPIVOTDATA("Sum of Discount %",Pivot!$A$110) -> 0.22 | S3: =GETPIVOTDATA("Sum of Net Sales (INR)",Pivot!$A$110) -> 26763.5 | V3: =GETPIVOTDATA("Sum of COGS (INR)",Pivot!$A$110) -> 15403.4 | Y3: =GETPIVOTDATA("Sum of Gross Profit (INR)",Pivot!$A$110) -> 11360.1

Sheet Expense Report
A1: Expense Report
A3: Department | B3: Expense Type | C3: Paid | D3: Pending | E3: Grand Total
A4: Admin | B4: Factory Electricity | C4: 16149 | E4: 16149
B5: Maintenance | C5: 20484 | E5: 20484
B6: Marketing | D6: 8319 | E6: 8319
B7: Packaging | C7: 15414 | D7: 6073 | E7: 21487
B8: Staff Wages | C8: 16618 | D8: 15617 | E8: 32235
B9: Transport | C9: 13237 | D9: 7056 | E9: 20293
B10: Warehouse Rent | C10: 4419 | D10: 9131 | E10: 13550
A11: Admin Total | C11: 86321 | D11: 46196 | E11: 132517
A12: Production | B12: Factory Electricity | C12: 46840 | E12: 46840
B13: Maintenance | C13: 13711 | E13: 13711
B14: Marketing | D14: 24304 | E14: 24304
B15: Packaging | C15: 27733 | D15: 15262 | E15: 42995
B16: Staff Wages | C16: 21609 | D16: 11102 | E16: 32711
B17: Transport | C17: 7567 | E17: 7567
B18: Warehouse Rent | D18: 31031 | E18: 31031
A19: Production Total | C19: 117460 | D19: 81699 | E19: 199159
A20: Sales | B20: Factory Electricity | C20: 4184 | E20: 4184
B21: Maintenance | C21: 22375 | E21: 22375
B22: Packaging | C22: 4105 | D22: 10255 | E22: 14360
B23: Staff Wages | C23: 23425 | E23: 23425
B24: Transport | D24: 9695 | E24: 9695
B25: Warehouse Rent | C25: 25173 | D25: 1571 | E25: 26744
A26: Sales Total | C26: 79262 | D26: 21521 | E26: 100783
A27: Warehouse | B27: Factory Electricity | C27: 3124 | D27: 4453 | E27: 7577
B28: Maintenance | C28: 925 | D28: 23889 | E28: 24814
B29: Marketing | C29: 37548 | D29: 9904 | E29: 47452
B30: Packaging | C30: 15346 | E30: 15346
B31: Staff Wages | C31: 21494 | E31: 21494
B32: Transport | C32: 13037 | E32: 13037
B33: Warehouse Rent | D33: 8717 | E33: 8717
A34: Warehouse Total | C34: 91474 | D34: 46963 | E34: 138437
A35: Grand Total | C35: 374517 | D35: 196379 | E35: 570896

Sheet Daily & Monthly Sales Report
A1: Daily Sales Report | I1: Monthly Sales Report
A3: Invoice Date | B3: Quantity | C3: Gross Sales (INR) | D3: Discount % | E3: Net Sales (INR) | F3: Gross Profit (INR) | I3: Customer Name | J3: Quantity | K3: Gross Sales (INR) | L3: Discount % | M3: Net Sales (INR) | N3: Gross Profit (INR)
A4: 46266 | B4: 2636 | C4: 88235 | D4: 0.34 | E4: 86334.9 | F4: 34584.6 | I4: A-One Distributors | J4: 3584 | K4: 170890 | L4: 0.26 | M4: 168911.15 | N4: 67934.05
A5: 46267 | B5: 1350 | C5: 46610 | D5: 0.14 | E5: 46338.2 | F5: 19287.3 | I5: City Supermarket | J5: 2929 | K5: 91970 | L5: 0.62 | M5: 89617.75 | N5: 36296.05
A6: 46268 | B6: 2124 | C6: 77120 | D6: 0.25 | E6: 75917.3 | F6: 31130.5 | I6: Daily Needs Store | J6: 3923 | K6: 118990 | L6: 0.65 | M6: 116424.25 | N6: 47668.55
A7: 46269 | B7: 1399 | C7: 46360 | D7: 0.23 | E7: 45346.5 | F7: 18634 | I7: Fresh Mart | J7: 3310 | K7: 128685 | L7: 0.53 | M7: 125925.15 | N7: 50974.75
A8: 46270 | B8: 1080 | C8: 37645 | D8: 0.22 | E8: 36843.2 | F8: 15204.1 | I8: Green Basket | J8: 3641 | K8: 135875 | L8: 0.43 | M8: 133564.85 | N8: 54663.95
A9: 46271 | B9: 2701 | C9: 124375 | D9: 0.41 | E9: 121822.4 | F9: 48743.4 | I9: Happy Family Store | J9: 3149 | K9: 103360 | L9: 0.46 | M9: 101770.8 | N9: 41893.2
A10: 46272 | B10: 1872 | C10: 71050 | D10: 0.35 | E10: 69450.65 | F10: 28191.85 | I10: Jai Maa Enterprises | J10: 4452 | K10: 149250 | L10: 0.7 | M10: 146077.7 | N10: 59995.5
A11: 46273 | B11: 1515 | C11: 65225 | D11: 0.24 | E11: 64423.55 | F11: 26387.55 | I11: Kumar Traders | J11: 3489 | K11: 123345 | L11: 0.52 | M11: 121419.7 | N11: 49547.6
A12: 46274 | B12: 1771 | C12: 52085 | D12: 0.27 | E12: 51027.6 | F12: 20844.9 | I12: Metro Foods Retail | J12: 5377 | K12: 204470 | L12: 0.62 | M12: 201293.9 | N12: 81675.5
A13: 46275 | B13: 777 | C13: 22750 | D13: 0.19 | E13: 22227 | F13: 9220.6 | I13: National Distributors | J13: 3138 | K13: 92870 | L13: 0.59 | M13: 90867.2 | N13: 37198.8
A14: 46276 | B14: 2583 | C14: 101060 | D14: 0.44 | E14: 99305.05 | F14: 40274.65 | I14: New India Mart | J14: 3740 | K14: 131785 | L14: 0.7 | M14: 128994.1 | N14: 52765.1
A15: 46277 | B15: 1972 | C15: 87110 | D15: 0.25 | E15: 85872.9 | F15: 34754.5 | I15: Om Wholesale | J15: 3421 | K15: 100220 | L15: 0.55 | M15: 98312.4 | N15: 40622.5
... A19: 46281 | B19: 2262 | C19: 89415 | D19: 0.38 | E19: 87509.5 | F19: 35383.1 | I19: Grand Total | J19: 53579 | K19: 1926910 | L19: 8.35 | M19: 1891331.1 | N19: 770248.05
A20: 46282 | B20: 2242 | C20: 84815 | D20: 0.29 | E20: 83150.1 | F20: 33363.5
A21: 46283 | B21: 1551 | C21: 42320 | D21: 0.14 | E21: 42139.8 | F21: 17672
A22: 46284 | B22: 1128 | C22: 25290 | D22: 0.3 | E22: 24747.95 | F22: 10417.95
A23: 46285 | B23: 2338 | C23: 81250 | D23: 0.2 | E23: 80080.15 | F23: 33137.85
A24: 46286 | B24: 1869 | C24: 47810 | D24: 0.34 | E24: 46703 | F24: 19081.3
A25: 46287 | B25: 1957 | C25: 74960 | D25: 0.38 | E25: 73516.65 | F25: 30010.35
A26: 46288 | B26: 1110 | C26: 27180 | D26: 0.22 | E26: 26763.5 | F26: 11360.1
A27: 46289 | B27: 690 | C27: 31750 | D27: 0.2 | E27: 31342.05 | F27: 12727.45
A28: 46290 | B28: 1827 | C28: 51265 | D28: 0.27 | E28: 50115.3 | F28: 20765.9
A29: 46291 | B29: 1101 | C29: 45485 | D29: 0.3 | E29: 43981.6 | F29: 17296.4
A30: 46292 | B30: 2509 | C30: 75450 | D30: 0.29 | E30: 74481.8 | F30: 31054.6
A31: 46293 | B31: 1848 | C31: 67980 | D31: 0.27 | E31: 66930.15 | F31: 27524.95
... A33: 46295 | B33: 1893 | C33: 74490 | D33: 0.23 | E33: 72897.1 | F33: 29338.3
A34: Grand Total | B34: 53579 | C34: 1926910 | D34: 8.35 | E34: 1891331.2 | F34: 770248.05

Sheet Product Report
A1: Product Wise Report
A3: Product Name | B3: Quantity | C3: Net Sales (INR) | D3: Gross Profit (INR)
A4: Tomato Ketchup 500g | B4: 8063 | C4: 672343.2 | D4: 261130.2
A5: Mixed Namkeen 200g | B5: 4484 | C5: 219406 | D5: 89370
A6: Chocolate Cookies 150g | B6: 5580 | C6: 219141.6 | D6: 90801.6
A7: Roasted Peanuts 100g | B7: 4561 | C7: 157531.85 | D7: 66311.85
A8: Mango Drink 200ml | B8: 4707 | C8: 116115.5 | D8: 50217.5
A9: Cream Biscuits 100g | B9: 5900 | C9: 115079.8 | D9: 50179.8
A10: Orange Drink 200ml | B10: 4593 | C10: 112925 | D10: 47704.4
A11: Masala Potato Chips | B11: 5630 | C11: 110187 | D11: 43753
A12: Instant Noodles 70g | B12: 5960 | C12: 87988.8 | D12: 37328.8
A13: Classic Potato Chips | B13: 4101 | C13: 80612.4 | D13: 33450.9
A14: Grand Total | B14: 53579 | C14: 1891331.2 | D14: 770248.05

Sheet Custome Report 
A1: Customer Contribution Report | F1: City Wise Sales Report
A3: Customer Name | B3: Quantity | C3: Net Sales (INR) | D3: Contribution | F3: Customer Name | G3: City | H3: Quantity | I3: Net Sales (INR) | J3: Gross Profit (INR)
A4: A-One Distributors | B4: 3584 | C4: 168911.15 | D4: =B4/$B$19 -> 0.066891879 | F4: A-One Distributors | G4: Karnal | H4: 3584 | I4: 168911.15 | J4: 67934.05
A5: City Supermarket | B5: 2929 | C5: 89617.75 | D5: =B5/$B$19 -> 0.05466694 | F5: City Supermarket | G5: Panipat | H5: 2929 | I5: 89617.75 | J5: 36296.05
A6: Daily Needs Store | B6: 3923 | C6: 116424.25 | D6: =B6/$B$19 -> 0.073218985 | F6: Daily Needs Store | G6: Gurugram | H6: 3923 | I6: 116424.25 | J6: 47668.55
A7: Fresh Mart | B7: 3310 | C7: 125925.15 | D7: =B7/$B$19 -> 0.061777935 | F7: Fresh Mart | G7: Sonipat | H7: 3310 | I7: 125925.15 | J7: 50974.75
A8: Green Basket | B8: 3641 | C8: 133564.85 | D8: =B8/$B$19 -> 0.067955729 | F8: Green Basket | G8: Faridabad | H8: 3641 | I8: 133564.85 | J8: 54663.95
A9: Happy Family Store | B9: 3149 | C9: 101770.8 | D9: =B9/$B$19 -> 0.058773027 | F9: Happy Family Store | G9: Delhi | H9: 3149 | I9: 101770.8 | J9: 41893.2
A10: Jai Maa Enterprises | B10: 4452 | C10: 146077.7 | D10: =B10/$B$19 -> 0.083092256 | F10: Jai Maa Enterprises | G10: Bahadurgarh | H10: 4452 | I10: 146077.7 | J10: 59995.5
A11: Kumar Traders | B11: 3489 | C11: 121419.7 | D11: =B11/$B$19 -> 0.065118797 | F11: Kumar Traders | G11: Rohtak | H11: 3489 | I11: 121419.7 | J11: 49547.6
A12: Metro Foods Retail | B12: 5377 | C12: 201293.9 | D12: =B12/$B$19 -> 0.10035648 | F12: Metro Foods Retail | G12: Noida | H12: 5377 | I12: 201293.9 | J12: 81675.5
A13: National Distributors | B13: 3138 | C13: 90867.2 | D13: =B13/$B$19 -> 0.058567722 | F13: National Distributors | G13: Chandigarh | H13: 3138 | I13: 90867.2 | J13: 37198.8
A14: New India Mart | B14: 3740 | C14: 128994.1 | D14: =B14/$B$19 -> 0.069803468 | F14: New India Mart | G14: Ghaziabad | H14: 3740 | I14: 128994.1 | J14: 52765.1
A15: Om Wholesale | B15: 3421 | C15: 98312.4 | D15: =B15/$B$19 -> 0.063849643 | F15: Om Wholesale | G15: Ambala | H15: 3421 | I15: 98312.4 | J15: 40622.5
... A18: Shree Balaji Store | B18: 3435 | C18: 154821.75 | D18: =B18/$B$19 -> 0.064110939 | F18: Shree Balaji Store | G18: Meerut | H18: 3435 | I18: 154821.75 | J18: 62247.85
A19: Grand Total | B19: 53579 | C19: 1891331.1 | D19: =B19/$B$19 -> 1 | F19: Grand Total | H19: 53579 | I19: 1891331.1 | J19: 770248.05
